Traceback (most recent call last):
  File "/home/shashank23088/Documents/shashank/adl_project/CoPaint/main.py", line 351, in <module>
    main()
  File "/home/shashank23088/Documents/shashank/adl_project/CoPaint/main.py", line 157, in main
    datas = prepare_data(
            ^^^^^^^^^^^^^
  File "/home/shashank23088/Documents/shashank/adl_project/CoPaint/main.py", line 92, in prepare_data
    datas = load_lama_celebahq(mask_type=mask_type)
            ^^^^^^^^^^^^^^^^^^^^^^^^^^^^^^^^^^^^^^^
  File "/home/shashank23088/Documents/shashank/adl_project/CoPaint/datasets/celebahq.py", line 78, in load_lama_celebahq
    mask_paths = _list_image_files_recursively(mask_dir)
                 ^^^^^^^^^^^^^^^^^^^^^^^^^^^^^^^^^^^^^^^
  File "/home/shashank23088/Documents/shashank/adl_project/CoPaint/datasets/utils.py", line 27, in _list_image_files_recursively
    for entry in sorted(bf.listdir(data_dir)):
                 ^^^^^^^^^^^^^^^^^^^^^^^^^^^^
  File "/home/shashank23088/anaconda3/envs/copaint/lib/python3.12/site-packages/blobfile/_context.py", line 344, in listdir
    for entry in self.scandir(path, shard_prefix_length=shard_prefix_length):
                 ^^^^^^^^^^^^^^^^^^^^^^^^^^^^^^^^^^^^^^^^^^^^^^^^^^^^^^^^^^^
  File "/home/shashank23088/anaconda3/envs/copaint/lib/python3.12/site-packages/blobfile/_context.py", line 352, in scandir
    raise FileNotFoundError(f"The system cannot find the path specified: '{path}'")
FileNotFoundError: The system cannot find the path specified: '/home/shashank23088/Documents/shashank/adl_project/CoPaint/datasets/Repaint_mask/narrow'
